<?xml version="1.0"?>
<!-- created with Phobos 1.0.1 "Capricious Choutengan" -->
<robot name="searcherbot" xmlns:xacro="http://www.ros.org/wiki/xacro">

  <xacro:include filename="$(find searcherbot_description)/urdf/colors.urdf.xacro"/>
  <xacro:include filename="$(find searcherbot_description)/urdf/sensors/laser.urdf.xacro"/>
  <xacro:include filename="$(find searcherbot_description)/urdf/sensors/camera.urdf.xacro"/>
  

  <link name="base_link">
    <inertial>
      <origin xyz="0 0 0" rpy="0 0 0"/>
      <mass value="5.0"/>
      <inertia ixx="0.00061" ixy="0" ixz="0" iyy="0.00061" iyz="0" izz="0.0002"/>
    </inertial>
    <visual>
      <origin xyz="0 0 0" rpy="0 0 0"/>
      <geometry>
        <box size="0.5 0.5 0.35"/>
      </geometry>
      <material name="BlueGlow"/>
    </visual>
    <collision name="base">
      <origin xyz="0 0 0" rpy="0 0 0"/>
      <geometry>
        <box size="0.5 0.5 0.35"/>
      </geometry>
    </collision>
  </link>

  <link name="camera_link">
    <inertial>
      <origin xyz="0 0 0" rpy="0 0 0"/>
      <mass value="0.75"/>
      <inertia ixx="0.00625" ixy="0" ixz="0" iyy="0.00078" iyz="0" izz="0.00578"/>
    </inertial>
    <visual>
      <origin xyz="0 0 0" rpy="0 0 0"/>
      <geometry>
        <box size="0.05 0.3 0.1"/>
      </geometry>
      <material name="Black"/>
    </visual>
    <collision name="camera">
      <origin xyz="0 0 0" rpy="0 0 0"/>
      <geometry>
        <box size="0.05 0.3 0.1"/>
      </geometry>
    </collision>
  </link>

  <link name="laser_link">
    <inertial>
      <origin xyz="0 0 0" rpy="0 0 0"/>
      <mass value="1.0"/>
      <inertia ixx="0.01349" ixy="0" ixz="0" iyy="0.01349" iyz="0" izz="0.00031"/>
    </inertial>
    <visual>
      <origin xyz="0 0 0" rpy="0 0 0"/>
      <geometry>
        <cylinder radius="0.025" length="0.4"/>
      </geometry>
      <material name="Red"/>
    </visual>
    <collision name="laser">
      <origin xyz="0 0 0" rpy="0 0 0"/>
      <geometry>
        <cylinder radius="0.025" length="0.4"/>
      </geometry>
    </collision>
  </link>

  <link name="left_wheel_link">
    <inertial>
      <origin xyz="0 0 0" rpy="0 0 0"/>
      <mass value="3.0"/>
      <inertia ixx="0.0775" ixy="0" ixz="0" iyy="0.135" iyz="0" izz="0.0775"/>
    </inertial>
    <visual>
      <origin xyz="0 0 0" rpy="0 0 0"/>
      <geometry>
        <cylinder radius="0.3" length="0.2"/>
      </geometry>
      <material name="DarkGrey"/>
    </visual>
    <collision name="left_wheel">
      <origin xyz="0 0 0" rpy="0 0 0"/>
      <geometry>
        <cylinder radius="0.3" length="0.2"/>
      </geometry>
    </collision>
  </link>

  <link name="right_wheel_link">
    <inertial>
      <origin xyz="0 0 0" rpy="0 0 0"/>
      <mass value="3.0"/>
      <inertia ixx="0.0775" ixy="0" ixz="0" iyy="0.135" iyz="0" izz="0.0775"/>
    </inertial>
    <visual>
      <origin xyz="0 0 0" rpy="0 0 0"/>
      <geometry>
        <cylinder radius="0.3" length="0.2"/>
      </geometry>
      <material name="DarkGrey"/>
    </visual>
    <collision name="right_wheel">
      <origin xyz="0 0 0" rpy="0 0 0"/>
      <geometry>
        <cylinder radius="0.3" length="0.2"/>
      </geometry>
    </collision>
  </link>

  <link name="support_link">
    <inertial>
      <origin xyz="0 0 0" rpy="0 0 0"/>
      <mass value="3.0"/>
      <inertia ixx="0.00625" ixy="0" ixz="0" iyy="0.00625" iyz="0" izz="0.00625"/>
    </inertial>
    <visual>
      <origin xyz="0 0 0" rpy="1.5708 0 0"/>
      <geometry>
        <sphere radius="0.125"/>
      </geometry>
      <material name="Grey"/>
    </visual>
    <collision name="support">
      <origin xyz="0 0 0" rpy="1.5708 0 0"/>
      <geometry>
        <sphere radius="0.125"/>
      </geometry>
    </collision>
  </link>

  <joint name="camera_joint" type="fixed">
    <origin xyz="0.225 0 0.225" rpy="0 0 0"/>
    <parent link="base_link"/>
    <child link="camera_link"/>
  </joint>

  <joint name="laser_joint" type="fixed">
    <origin xyz="0 0 0.375" rpy="0 0 0"/>
    <parent link="base_link"/>
    <child link="laser_link"/>
  </joint>

  <joint name="left_wheel_joint" type="continuous">
    <origin xyz="0 0.35 0" rpy="-1.5708 0 0"/>
    <parent link="base_link"/>
    <child link="left_wheel_link"/>
    <axis xyz="0 0 1.0"/>
    <limit effort="1000.0" velocity="5.0"/>
  </joint>

  <joint name="right_wheel_joint" type="continuous">
    <origin xyz="0 -0.35 0" rpy="-1.5708 0 0"/>
    <parent link="base_link"/>
    <child link="right_wheel_link"/>
    <axis xyz="0 0 1.0"/>
    <limit effort="1000.0" velocity="5.0"/>
  </joint>

  <joint name="support_joint" type="continuous">
    <origin xyz="0.11 0 -0.175" rpy="-1.5708 0 0"/>
    <parent link="base_link"/>
    <child link="support_link"/>
    <axis xyz="0 0 1.0"/>
    <limit effort="0" velocity="0"/>
  </joint>

  <!-- Adding Sensors -->
  <xacro:set_laser reference_frame="laser_link"/>
  <xacro:set_camera name="searcherbot_camera" reference_frame="camera_link"/>

  <!-- Differential drive controller  -->
  <gazebo>
    <plugin name="differential_drive_controller" filename="libgazebo_ros_diff_drive.so">
      <legacyMode>true</legacyMode>
      <rosDebugLevel>Debug</rosDebugLevel>
      <publishWheelTF>false</publishWheelTF>
      <robotNamespace>/</robotNamespace>
      <publishTf>1</publishTf>
      <publishWheelJointState>false</publishWheelJointState>
      <alwaysOn>true</alwaysOn>
      <updateRate>100.0</updateRate>
      <leftJoint>left_wheel_joint</leftJoint>
      <rightJoint>right_wheel_joint</rightJoint>
      <wheelSeparation>0.5</wheelSeparation>
      <wheelDiameter>0.6</wheelDiameter>
      <broadcastTF>1</broadcastTF>
      <wheelTorque>30</wheelTorque>
      <wheelAcceleration>1.8</wheelAcceleration>
      <commandTopic>cmd_vel</commandTopic>
      <odometryFrame>odom</odometryFrame> 
      <odometryTopic>odom</odometryTopic> 
      <robotBaseFrame>base_link</robotBaseFrame>

    </plugin>
  </gazebo> 

</robot>
