<?xml version="1.0" ?>
<!-- =================================================================================== -->
<!-- |    This document was autogenerated by xacro from searcherbot.xacro              | -->
<!-- |    EDITING THIS FILE BY HAND IS NOT RECOMMENDED                                 | -->
<!-- =================================================================================== -->
<!-- created with Phobos 1.0.1 "Capricious Choutengan" -->
<robot name="searcherbot">
  <material name="Gray">
    <color rgba="0.5 0.5 0.5 1"/>
  </material>
  <material name="DarkGray">
    <color rgba="0.1 0.1 0.1 0.5"/>
  </material>
  <material name="Black">
    <color rgba="0 0 0 1"/>
  </material>
  <material name="Red">
    <color rgba="1 0 0 1"/>
  </material>
  <material name="BlueGlow">
    <color rgba="0.5 0.5 0.5 1"/>
  </material>
  <material name="Yellow">
    <color rgba="1 1 0 1"/>
  </material>
  <gazebo reference="base_link">
    <material>Gazebo/BlueGlow</material>
  </gazebo>
  <gazebo reference="camera_link">
    <material>Gazebo/Black</material>
  </gazebo>
  <gazebo reference="laser_link">
    <material>Gazebo/Red</material>
  </gazebo>
  <gazebo reference="left_wheel_link">
    <material>Gazebo/DarkGrey</material>
  </gazebo>
  <gazebo reference="right_wheel_link">
    <material>Gazebo/DarkGrey</material>
  </gazebo>
  <gazebo reference="support_link">
    <material>Gazebo/Grey</material>
  </gazebo>
  <gazebo reference="support_link2">
    <material>Gazebo/Yellow</material>
  </gazebo>
  <link name="base_footprint">
    <inertial>
      <mass value="0.0001"/>
      <origin xyz="0 0 0"/>
      <inertia ixx="0.0001" ixy="0.0" ixz="0.0" iyy="0.0001" iyz="0.0" izz="0.0001"/>
    </inertial>
    <visual>
      <origin rpy="0 0 0" xyz="0 0 0"/>
      <geometry>
        <box size="0.001 0.001 0.001"/>
      </geometry>
    </visual>
  </link>
  <gazebo reference="base_footprint">
    <turnGravityOff>false</turnGravityOff>
  </gazebo>
  <link name="base_link">
    <inertial>
      <origin rpy="0 0 0" xyz="0 0 0"/>
      <mass value="5.0"/>
      <inertia ixx="0.00061" ixy="0" ixz="0" iyy="0.00061" iyz="0" izz="0.0002"/>
    </inertial>
    <visual>
      <origin rpy="0 0 0" xyz="0 0 0"/>
      <geometry>
        <box size="0.5 0.5 0.35"/>
      </geometry>
      <material name="BlueGlow"/>
    </visual>
    <collision name="base">
      <origin rpy="0 0 0" xyz="0 0 0"/>
      <geometry>
        <box size="0.5 0.5 0.35"/>
      </geometry>
    </collision>
  </link>
  <link name="camera_link">
    <inertial>
      <origin rpy="0 0 0" xyz="0 0 0"/>
      <mass value="0.75"/>
      <inertia ixx="0.00625" ixy="0" ixz="0" iyy="0.00078" iyz="0" izz="0.00578"/>
    </inertial>
    <visual>
      <origin rpy="0 0 0" xyz="0 0 0"/>
      <geometry>
        <box size="0.05 0.3 0.1"/>
      </geometry>
      <material name="Black"/>
    </visual>
    <collision name="camera">
      <origin rpy="0 0 0" xyz="0 0 0"/>
      <geometry>
        <box size="0.05 0.3 0.1"/>
      </geometry>
    </collision>
  </link>
  <link name="laser_link">
    <inertial>
      <origin rpy="0 0 0" xyz="0 0 0"/>
      <mass value="1.0"/>
      <inertia ixx="0.01349" ixy="0" ixz="0" iyy="0.01349" iyz="0" izz="0.00031"/>
    </inertial>
    <visual>
      <origin rpy="0 0 0" xyz="0 0 0"/>
      <geometry>
        <cylinder length="0.4" radius="0.025"/>
      </geometry>
      <material name="Red"/>
    </visual>
    <collision name="laser">
      <origin rpy="0 0 0" xyz="0 0 0"/>
      <geometry>
        <cylinder length="0.4" radius="0.025"/>
      </geometry>
    </collision>
  </link>
  <link name="left_wheel_link">
    <inertial>
      <origin rpy="0 0 0" xyz="0 0 0"/>
      <mass value="3.0"/>
      <inertia ixx="0.0775" ixy="0" ixz="0" iyy="0.135" iyz="0" izz="0.0775"/>
    </inertial>
    <visual>
      <origin rpy="0 0 0" xyz="0 0 0"/>
      <geometry>
        <cylinder length="0.2" radius="0.3"/>
      </geometry>
      <material name="DarkGrey"/>
    </visual>
    <collision name="left_wheel">
      <origin rpy="0 0 0" xyz="0 0 0"/>
      <geometry>
        <cylinder length="0.2" radius="0.3"/>
      </geometry>
    </collision>
  </link>
  <link name="right_wheel_link">
    <inertial>
      <origin rpy="0 0 0" xyz="0 0 0"/>
      <mass value="3.0"/>
      <inertia ixx="0.0775" ixy="0" ixz="0" iyy="0.135" iyz="0" izz="0.0775"/>
    </inertial>
    <visual>
      <origin rpy="0 0 0" xyz="0 0 0"/>
      <geometry>
        <cylinder length="0.2" radius="0.3"/>
      </geometry>
      <material name="DarkGrey"/>
    </visual>
    <collision name="right_wheel">
      <origin rpy="0 0 0" xyz="0 0 0"/>
      <geometry>
        <cylinder length="0.2" radius="0.3"/>
      </geometry>
    </collision>
  </link>
  <link name="support_link">
    <inertial>
      <origin rpy="0 0 0" xyz="0 0 0"/>
      <mass value="3.0"/>
      <inertia ixx="0.00625" ixy="0" ixz="0" iyy="0.00625" iyz="0" izz="0.00625"/>
    </inertial>
    <visual>
      <origin rpy="1.5708 0 0" xyz="0 0 0"/>
      <geometry>
        <sphere radius="0.125"/>
      </geometry>
      <material name="Grey"/>
    </visual>
    <collision name="support">
      <origin rpy="1.5708 0 0" xyz="0 0 0"/>
      <geometry>
        <sphere radius="0.125"/>
      </geometry>
    </collision>
  </link>
  <link name="support_link2">
    <inertial>
      <origin rpy="0 0 0" xyz="0 0 0"/>
      <mass value="3.0"/>
      <inertia ixx="0.00625" ixy="0" ixz="0" iyy="0.00625" iyz="0" izz="0.00625"/>
    </inertial>
    <visual>
      <origin rpy="1.5708 0 0" xyz="0 0 0"/>
      <geometry>
        <sphere radius="0.125"/>
      </geometry>
      <material name="Yellow"/>
    </visual>
    <collision name="support2">
      <origin rpy="1.5708 0 0" xyz="0 0 0"/>
      <geometry>
        <sphere radius="0.125"/>
      </geometry>
    </collision>
  </link>
  <joint name="base_footprint_joint" type="fixed">
    <origin rpy="0 0 0" xyz="0 0 0.3"/>
    <parent link="base_footprint"/>
    <child link="base_link"/>
  </joint>
  <joint name="camera_joint" type="fixed">
    <origin rpy="0 0 0" xyz="0.225 0 0.225"/>
    <parent link="base_link"/>
    <child link="camera_link"/>
  </joint>
  <joint name="laser_joint" type="fixed">
    <origin rpy="0 0 0" xyz="0 0 0.375"/>
    <parent link="base_link"/>
    <child link="laser_link"/>
  </joint>
  <joint name="left_wheel_joint" type="continuous">
    <origin rpy="-1.5708 0 0" xyz="0 0.35 0"/>
    <parent link="base_link"/>
    <child link="left_wheel_link"/>
    <axis xyz="0 0 1.0"/>
    <limit effort="100.0" velocity="5.0"/>
  </joint>
  <joint name="right_wheel_joint" type="continuous">
    <origin rpy="-1.5708 0 0" xyz="0 -0.35 0"/>
    <parent link="base_link"/>
    <child link="right_wheel_link"/>
    <axis xyz="0 0 1.0"/>
    <limit effort="100.0" velocity="5.0"/>
  </joint>
  <joint name="support_joint" type="continuous">
    <origin rpy="-1.5708 0 0" xyz="0.11 0 -0.175"/>
    <parent link="base_link"/>
    <child link="support_link"/>
    <axis xyz="0 0 1.0"/>
    <limit effort="0" velocity="0"/>
  </joint>
  <joint name="support_joint2" type="continuous">
    <origin rpy="-1.5708 0 0" xyz="-0.15 0 -0.175"/>
    <parent link="base_link"/>
    <child link="support_link2"/>
    <axis xyz="0 0 1.0"/>
    <limit effort="0" velocity="0"/>
  </joint>
  <transmission name="left_wheel_joint_trans">
    <type>transmission_interface/SimpleTransmission</type>
    <joint name="left_wheel_joint"/>
    <actuator naem="left_wheel_joint_motor">
      <hardwareInterface>EffortJointInterface</hardwareInterface>
      <mechanicalReduction>1.0</mechanicalReduction>
    </actuator>
  </transmission>
  <transmission name="right_wheel_joint_trans">
    <type>transmission_interface/SimpleTransmission</type>
    <joint name="right_wheel_joint"/>
    <actuator naem="right_wheel_joint_motor">
      <hardwareInterface>EffortJointInterface</hardwareInterface>
      <mechanicalReduction>1.0</mechanicalReduction>
    </actuator>
  </transmission>
  <gazebo reference="laser_link">
    <turnGravityOff>false</turnGravityOff>
    <sensor name="laser360_sensor" type="ray">
      <pose>0 0 0 0 0 0</pose>
      <visualize>false</visualize>
      <update_rate>40</update_rate>
      <ray>
        <scan>
          <horizontal>
            <samples>720</samples>
            <resolution>1</resolution>
            <min_angle>-1.57</min_angle>
            <max_angle>1.57</max_angle>
          </horizontal>
        </scan>
        <range>
          <min>0.10</min>
          <max>10.0</max>
          <resolution>0.001</resolution>
        </range>
      </ray>
      <plugin filename="libgazebo_ros_laser.so" name="gazebo_ros_laser_controller">
        <topicName>/scan</topicName>
        <frameName>laser_link</frameName>
      </plugin>
    </sensor>
  </gazebo>
  <gazebo reference="camera_link">
    <visual>
      <pose>0 0 0 0 0 0 0</pose>
      <geometry>
        <sphere>
          <radius>.05</radius>
        </sphere>
      </geometry>
    </visual>
    <sensor name="searcherbot_camera" type="camera">
      <pose>0.0 0 0 0 0 0</pose>
      <update_rate>20.00</update_rate>
      <camera name="searcherbot_camera">
        <horizontal_fov>1.570000</horizontal_fov>
        <image>
          <width>320</width>
          <height>240</height>
          <format>RGB888</format>
        </image>
        <clip>
          <near>0.100000</near>
          <far>15.000000</far>
        </clip>
      </camera>
      <plugin filename="libgazebo_ros_camera.so" name="camera_controller">
        <alwaysOn>true</alwaysOn>
        <updateRate>0.0</updateRate>
        <cameraName>searcherbot_camera</cameraName>
        <imageTopicName>image_raw</imageTopicName>
        <cameraInfoTopicName>camera_info</cameraInfoTopicName>
        <frameName>camera_link</frameName>
        <hackBaseline>0.07</hackBaseline>
        <distortionK1>0.0</distortionK1>
        <distortionK2>0.0</distortionK2>
        <distortionK3>0.0</distortionK3>
        <distortionT1>0.0</distortionT1>
        <distortionT2>0.0</distortionT2>
      </plugin>
    </sensor>
  </gazebo>
  <!-- Differential drive controller  -->
  <gazebo>
    <plugin filename="libgazebo_ros_diff_drive.so" name="differential_drive_controller">
      <legacyMode>true</legacyMode>
      <rosDebugLevel>Debug</rosDebugLevel>
      <publishWheelTF>false</publishWheelTF>
      <robotNamespace>/</robotNamespace>
      <publishTf>1</publishTf>
      <publishWheelJointState>false</publishWheelJointState>
      <alwaysOn>true</alwaysOn>
      <updateRate>100.0</updateRate>
      <leftJoint>left_wheel_joint</leftJoint>
      <rightJoint>right_wheel_joint</rightJoint>
      <wheelSeparation>0.5</wheelSeparation>
      <wheelDiameter>0.6</wheelDiameter>
      <broadcastTF>1</broadcastTF>
      <wheelTorque>30</wheelTorque>
      <wheelAcceleration>1.8</wheelAcceleration>
      <commandTopic>cmd_vel</commandTopic>
      <odometryFrame>odom</odometryFrame>
      <odometryTopic>odom</odometryTopic>
      <robotBaseFrame>base_footprint</robotBaseFrame>
    </plugin>
  </gazebo>
</robot>

